Exception in thread django-main-thread:
Traceback (most recent call last):
  File "/usr/lib/python3.10/threading.py", line 1016, in _bootstrap_inner
    self.run()
  File "/usr/lib/python3.10/threading.py", line 953, in run
    self._target(*self._args, **self._kwargs)
  File "/home/dell/mystorevenv/lib/python3.10/site-packages/django/utils/autoreload.py", line 64, in wrapper
    fn(*args, **kwargs)
  File "/home/dell/mystorevenv/lib/python3.10/site-packages/django/core/management/commands/runserver.py", line 134, in inner_run
    self.check(display_num_errors=True)
  File "/home/dell/mystorevenv/lib/python3.10/site-packages/django/core/management/base.py", line 486, in check
    all_issues = checks.run_checks(
  File "/home/dell/mystorevenv/lib/python3.10/site-packages/django/core/checks/registry.py", line 88, in run_checks
    new_errors = check(app_configs=app_configs, databases=databases)
  File "/home/dell/mystorevenv/lib/python3.10/site-packages/django/core/checks/urls.py", line 44, in check_url_namespaces_unique
    all_namespaces = _load_all_namespaces(resolver)
  File "/home/dell/mystorevenv/lib/python3.10/site-packages/django/core/checks/urls.py", line 63, in _load_all_namespaces
    url_patterns = getattr(resolver, "url_patterns", [])
  File "/home/dell/mystorevenv/lib/python3.10/site-packages/django/utils/functional.py", line 47, in __get__
    res = instance.__dict__[self.name] = self.func(instance)
  File "/home/dell/mystorevenv/lib/python3.10/site-packages/django/urls/resolvers.py", line 718, in url_patterns
    patterns = getattr(self.urlconf_module, "urlpatterns", self.urlconf_module)
  File "/home/dell/mystorevenv/lib/python3.10/site-packages/django/utils/functional.py", line 47, in __get__
    res = instance.__dict__[self.name] = self.func(instance)
  File "/home/dell/mystorevenv/lib/python3.10/site-packages/django/urls/resolvers.py", line 711, in urlconf_module
    return import_module(self.urlconf_name)
  File "/usr/lib/python3.10/importlib/__init__.py", line 126, in import_module
    return _bootstrap._gcd_import(name[level:], package, level)
  File "<frozen importlib._bootstrap>", line 1050, in _gcd_import
  File "<frozen importlib._bootstrap>", line 1027, in _find_and_load
  File "<frozen importlib._bootstrap>", line 1006, in _find_and_load_unlocked
  File "<frozen importlib._bootstrap>", line 688, in _load_unlocked
  File "<frozen importlib._bootstrap_external>", line 883, in exec_module
  File "<frozen importlib._bootstrap>", line 241, in _call_with_frames_removed
  File "/home/dell/mystore/mystore/urls.py", line 25, in <module>
    path('customers/',include('customers.urls')),
  File "/home/dell/mystorevenv/lib/python3.10/site-packages/django/urls/conf.py", line 39, in include
    urlconf_module = import_module(urlconf_module)
  File "/usr/lib/python3.10/importlib/__init__.py", line 126, in import_module
    return _bootstrap._gcd_import(name[level:], package, level)
  File "<frozen importlib._bootstrap>", line 1050, in _gcd_import
  File "<frozen importlib._bootstrap>", line 1027, in _find_and_load
  File "<frozen importlib._bootstrap>", line 1006, in _find_and_load_unlocked
  File "<frozen importlib._bootstrap>", line 688, in _load_unlocked
  File "<frozen importlib._bootstrap_external>", line 883, in exec_module
  File "<frozen importlib._bootstrap>", line 241, in _call_with_frames_removed
  File "/home/dell/mystore/customers/urls.py", line 5, in <module>
    from . import views
  File "/home/dell/mystore/customers/views.py", line 12
    email=request.POST.get('email)
                           ^
SyntaxError: unterminated string literal (detected at line 12)
/home/dell/mystore/customers/views.py changed, reloading.
Watching for file changes with StatReloader
Performing system checks...

System check identified some issues:

WARNINGS:
customers.Customer.phone: (fields.W122) 'max_length' is ignored when used with IntegerField.
        HINT: Remove 'max_length' from field

System check identified 1 issue (0 silenced).
October 31, 2024 - 21:13:23
Django version 5.1, using settings 'mystore.settings'
Starting development server at http://127.0.0.1:8000/
Quit the server with CONTROL-C.

/home/dell/mystore/customers/models.py changed, reloading.
Watching for file changes with StatReloader
Performing system checks...

System check identified some issues:

WARNINGS:
customers.Customer.phone: (fields.W122) 'max_length' is ignored when used with IntegerField.
        HINT: Remove 'max_length' from field

System check identified 1 issue (0 silenced).
October 31, 2024 - 21:15:27
Django version 5.1, using settings 'mystore.settings'
Starting development server at http://127.0.0.1:8000/
Quit the server with CONTROL-C.

/home/dell/mystore/customers/models.py changed, reloading.
Watching for file changes with StatReloader
Exception in thread django-main-thread:
Traceback (most recent call last):
  File "/usr/lib/python3.10/threading.py", line 1016, in _bootstrap_inner
    self.run()
  File "/usr/lib/python3.10/threading.py", line 953, in run
    self._target(*self._args, **self._kwargs)
  File "/home/dell/mystorevenv/lib/python3.10/site-packages/django/utils/autoreload.py", line 64, in wrapper
    fn(*args, **kwargs)
  File "/home/dell/mystorevenv/lib/python3.10/site-packages/django/core/management/commands/runserver.py", line 126, in inner_run
    autoreload.raise_last_exception()
  File "/home/dell/mystorevenv/lib/python3.10/site-packages/django/utils/autoreload.py", line 87, in raise_last_exception
    raise _exception[1]
  File "/home/dell/mystorevenv/lib/python3.10/site-packages/django/core/management/__init__.py", line 394, in execute
    autoreload.check_errors(django.setup)()
  File "/home/dell/mystorevenv/lib/python3.10/site-packages/django/utils/autoreload.py", line 64, in wrapper
    fn(*args, **kwargs)
  File "/home/dell/mystorevenv/lib/python3.10/site-packages/django/__init__.py", line 24, in setup
    apps.populate(settings.INSTALLED_APPS)
  File "/home/dell/mystorevenv/lib/python3.10/site-packages/django/apps/registry.py", line 116, in populate
    app_config.import_models()
  File "/home/dell/mystorevenv/lib/python3.10/site-packages/django/apps/config.py", line 269, in import_models
    self.models_module = import_module(models_module_name)
  File "/usr/lib/python3.10/importlib/__init__.py", line 126, in import_module
    return _bootstrap._gcd_import(name[level:], package, level)
  File "<frozen importlib._bootstrap>", line 1050, in _gcd_import
  File "<frozen importlib._bootstrap>", line 1027, in _find_and_load
  File "<frozen importlib._bootstrap>", line 1006, in _find_and_load_unlocked
  File "<frozen importlib._bootstrap>", line 688, in _load_unlocked
  File "<frozen importlib._bootstrap_external>", line 883, in exec_module
  File "<frozen importlib._bootstrap>", line 241, in _call_with_frames_removed
  File "/home/dell/mystore/customers/models.py", line 5, in <module>
    class Customer(models.Model):
  File "/home/dell/mystore/customers/models.py", line 10, in Customer
    password
NameError: name 'password' is not defined
/home/dell/mystore/customers/models.py changed, reloading.
Watching for file changes with StatReloader
Exception in thread django-main-thread:
Traceback (most recent call last):
  File "/usr/lib/python3.10/threading.py", line 1016, in _bootstrap_inner
    self.run()
  File "/usr/lib/python3.10/threading.py", line 953, in run
    self._target(*self._args, **self._kwargs)
  File "/home/dell/mystorevenv/lib/python3.10/site-packages/django/utils/autoreload.py", line 64, in wrapper
    fn(*args, **kwargs)
  File "/home/dell/mystorevenv/lib/python3.10/site-packages/django/core/management/commands/runserver.py", line 126, in inner_run
    autoreload.raise_last_exception()
  File "/home/dell/mystorevenv/lib/python3.10/site-packages/django/utils/autoreload.py", line 87, in raise_last_exception
    raise _exception[1]
  File "/home/dell/mystorevenv/lib/python3.10/site-packages/django/core/management/__init__.py", line 394, in execute
    autoreload.check_errors(django.setup)()
  File "/home/dell/mystorevenv/lib/python3.10/site-packages/django/utils/autoreload.py", line 64, in wrapper
    fn(*args, **kwargs)
  File "/home/dell/mystorevenv/lib/python3.10/site-packages/django/__init__.py", line 24, in setup
    apps.populate(settings.INSTALLED_APPS)
  File "/home/dell/mystorevenv/lib/python3.10/site-packages/django/apps/registry.py", line 116, in populate
    app_config.import_models()
  File "/home/dell/mystorevenv/lib/python3.10/site-packages/django/apps/config.py", line 269, in import_models
    self.models_module = import_module(models_module_name)
  File "/usr/lib/python3.10/importlib/__init__.py", line 126, in import_module
    return _bootstrap._gcd_import(name[level:], package, level)
  File "<frozen importlib._bootstrap>", line 1050, in _gcd_import
  File "<frozen importlib._bootstrap>", line 1027, in _find_and_load
  File "<frozen importlib._bootstrap>", line 1006, in _find_and_load_unlocked
  File "<frozen importlib._bootstrap>", line 688, in _load_unlocked
  File "<frozen importlib._bootstrap_external>", line 879, in exec_module
  File "<frozen importlib._bootstrap_external>", line 1017, in get_code
  File "<frozen importlib._bootstrap_external>", line 947, in source_to_code
  File "<frozen importlib._bootstrap>", line 241, in _call_with_frames_removed
  File "/home/dell/mystore/customers/models.py", line 10
    password = 
               ^
SyntaxError: invalid syntax
/home/dell/mystore/customers/models.py changed, reloading.
Watching for file changes with StatReloader
Exception in thread django-main-thread:
Traceback (most recent call last):
  File "/usr/lib/python3.10/threading.py", line 1016, in _bootstrap_inner
    self.run()
  File "/usr/lib/python3.10/threading.py", line 953, in run
    self._target(*self._args, **self._kwargs)
  File "/home/dell/mystorevenv/lib/python3.10/site-packages/django/utils/autoreload.py", line 64, in wrapper
    fn(*args, **kwargs)
  File "/home/dell/mystorevenv/lib/python3.10/site-packages/django/core/management/commands/runserver.py", line 126, in inner_run
    autoreload.raise_last_exception()
  File "/home/dell/mystorevenv/lib/python3.10/site-packages/django/utils/autoreload.py", line 87, in raise_last_exception
    raise _exception[1]
  File "/home/dell/mystorevenv/lib/python3.10/site-packages/django/core/management/__init__.py", line 394, in execute
    autoreload.check_errors(django.setup)()
  File "/home/dell/mystorevenv/lib/python3.10/site-packages/django/utils/autoreload.py", line 64, in wrapper
    fn(*args, **kwargs)
  File "/home/dell/mystorevenv/lib/python3.10/site-packages/django/__init__.py", line 24, in setup
    apps.populate(settings.INSTALLED_APPS)
  File "/home/dell/mystorevenv/lib/python3.10/site-packages/django/apps/registry.py", line 116, in populate
    app_config.import_models()
  File "/home/dell/mystorevenv/lib/python3.10/site-packages/django/apps/config.py", line 269, in import_models
    self.models_module = import_module(models_module_name)
  File "/usr/lib/python3.10/importlib/__init__.py", line 126, in import_module
    return _bootstrap._gcd_import(name[level:], package, level)
  File "<frozen importlib._bootstrap>", line 1050, in _gcd_import
  File "<frozen importlib._bootstrap>", line 1027, in _find_and_load
  File "<frozen importlib._bootstrap>", line 1006, in _find_and_load_unlocked
  File "<frozen importlib._bootstrap>", line 688, in _load_unlocked
  File "<frozen importlib._bootstrap_external>", line 883, in exec_module
  File "<frozen importlib._bootstrap>", line 241, in _call_with_frames_removed
  File "/home/dell/mystore/customers/models.py", line 5, in <module>
    class Customer(models.Model):
  File "/home/dell/mystore/customers/models.py", line 10, in Customer
    password = mod
NameError: name 'mod' is not defined
/home/dell/mystore/customers/models.py changed, reloading.
Watching for file changes with StatReloader
Exception in thread django-main-thread:
Traceback (most recent call last):
  File "/usr/lib/python3.10/threading.py", line 1016, in _bootstrap_inner
    self.run()
  File "/usr/lib/python3.10/threading.py", line 953, in run
    self._target(*self._args, **self._kwargs)
  File "/home/dell/mystorevenv/lib/python3.10/site-packages/django/utils/autoreload.py", line 64, in wrapper
    fn(*args, **kwargs)
  File "/home/dell/mystorevenv/lib/python3.10/site-packages/django/core/management/commands/runserver.py", line 126, in inner_run
    autoreload.raise_last_exception()
  File "/home/dell/mystorevenv/lib/python3.10/site-packages/django/utils/autoreload.py", line 87, in raise_last_exception
    raise _exception[1]
  File "/home/dell/mystorevenv/lib/python3.10/site-packages/django/core/management/__init__.py", line 394, in execute
    autoreload.check_errors(django.setup)()
  File "/home/dell/mystorevenv/lib/python3.10/site-packages/django/utils/autoreload.py", line 64, in wrapper
    fn(*args, **kwargs)
  File "/home/dell/mystorevenv/lib/python3.10/site-packages/django/__init__.py", line 24, in setup
    apps.populate(settings.INSTALLED_APPS)
  File "/home/dell/mystorevenv/lib/python3.10/site-packages/django/apps/registry.py", line 116, in populate
    app_config.import_models()
  File "/home/dell/mystorevenv/lib/python3.10/site-packages/django/apps/config.py", line 269, in import_models
    self.models_module = import_module(models_module_name)
  File "/usr/lib/python3.10/importlib/__init__.py", line 126, in import_module
    return _bootstrap._gcd_import(name[level:], package, level)
  File "<frozen importlib._bootstrap>", line 1050, in _gcd_import
  File "<frozen importlib._bootstrap>", line 1027, in _find_and_load
  File "<frozen importlib._bootstrap>", line 1006, in _find_and_load_unlocked
  File "<frozen importlib._bootstrap>", line 688, in _load_unlocked
  File "<frozen importlib._bootstrap_external>", line 879, in exec_module
  File "<frozen importlib._bootstrap_external>", line 1017, in get_code
  File "<frozen importlib._bootstrap_external>", line 947, in source_to_code
  File "<frozen importlib._bootstrap>", line 241, in _call_with_frames_removed
  File "/home/dell/mystore/customers/models.py", line 10
    password = models.
                      ^
SyntaxError: invalid syntax
/home/dell/mystore/customers/models.py changed, reloading.
Watching for file changes with StatReloader
Exception in thread django-main-thread:
Traceback (most recent call last):
  File "/usr/lib/python3.10/threading.py", line 1016, in _bootstrap_inner
    self.run()
  File "/usr/lib/python3.10/threading.py", line 953, in run
    self._target(*self._args, **self._kwargs)
  File "/home/dell/mystorevenv/lib/python3.10/site-packages/django/utils/autoreload.py", line 64, in wrapper
    fn(*args, **kwargs)
  File "/home/dell/mystorevenv/lib/python3.10/site-packages/django/core/management/commands/runserver.py", line 126, in inner_run
    autoreload.raise_last_exception()
  File "/home/dell/mystorevenv/lib/python3.10/site-packages/django/utils/autoreload.py", line 87, in raise_last_exception
    raise _exception[1]
  File "/home/dell/mystorevenv/lib/python3.10/site-packages/django/core/management/__init__.py", line 394, in execute
    autoreload.check_errors(django.setup)()
  File "/home/dell/mystorevenv/lib/python3.10/site-packages/django/utils/autoreload.py", line 64, in wrapper
    fn(*args, **kwargs)
  File "/home/dell/mystorevenv/lib/python3.10/site-packages/django/__init__.py", line 24, in setup
    apps.populate(settings.INSTALLED_APPS)
  File "/home/dell/mystorevenv/lib/python3.10/site-packages/django/apps/registry.py", line 116, in populate
    app_config.import_models()
  File "/home/dell/mystorevenv/lib/python3.10/site-packages/django/apps/config.py", line 269, in import_models
    self.models_module = import_module(models_module_name)
  File "/usr/lib/python3.10/importlib/__init__.py", line 126, in import_module
    return _bootstrap._gcd_import(name[level:], package, level)
  File "<frozen importlib._bootstrap>", line 1050, in _gcd_import
  File "<frozen importlib._bootstrap>", line 1027, in _find_and_load
  File "<frozen importlib._bootstrap>", line 1006, in _find_and_load_unlocked
  File "<frozen importlib._bootstrap>", line 688, in _load_unlocked
  File "<frozen importlib._bootstrap_external>", line 883, in exec_module
  File "<frozen importlib._bootstrap>", line 241, in _call_with_frames_removed
  File "/home/dell/mystore/customers/models.py", line 5, in <module>
    class Customer(models.Model):
  File "/home/dell/mystore/customers/models.py", line 10, in Customer
    password = models.P
AttributeError: module 'django.db.models' has no attribute 'P'
/home/dell/mystore/customers/models.py changed, reloading.
Watching for file changes with StatReloader
Exception in thread django-main-thread:
Traceback (most recent call last):
  File "/usr/lib/python3.10/threading.py", line 1016, in _bootstrap_inner
    self.run()
  File "/usr/lib/python3.10/threading.py", line 953, in run
    self._target(*self._args, **self._kwargs)
  File "/home/dell/mystorevenv/lib/python3.10/site-packages/django/utils/autoreload.py", line 64, in wrapper
    fn(*args, **kwargs)
  File "/home/dell/mystorevenv/lib/python3.10/site-packages/django/core/management/commands/runserver.py", line 126, in inner_run
    autoreload.raise_last_exception()
  File "/home/dell/mystorevenv/lib/python3.10/site-packages/django/utils/autoreload.py", line 87, in raise_last_exception
    raise _exception[1]
  File "/home/dell/mystorevenv/lib/python3.10/site-packages/django/core/management/__init__.py", line 394, in execute
    autoreload.check_errors(django.setup)()
  File "/home/dell/mystorevenv/lib/python3.10/site-packages/django/utils/autoreload.py", line 64, in wrapper
    fn(*args, **kwargs)
  File "/home/dell/mystorevenv/lib/python3.10/site-packages/django/__init__.py", line 24, in setup
    apps.populate(settings.INSTALLED_APPS)
  File "/home/dell/mystorevenv/lib/python3.10/site-packages/django/apps/registry.py", line 116, in populate
    app_config.import_models()
  File "/home/dell/mystorevenv/lib/python3.10/site-packages/django/apps/config.py", line 269, in import_models
    self.models_module = import_module(models_module_name)
  File "/usr/lib/python3.10/importlib/__init__.py", line 126, in import_module
    return _bootstrap._gcd_import(name[level:], package, level)
  File "<frozen importlib._bootstrap>", line 1050, in _gcd_import
  File "<frozen importlib._bootstrap>", line 1027, in _find_and_load
  File "<frozen importlib._bootstrap>", line 1006, in _find_and_load_unlocked
  File "<frozen importlib._bootstrap>", line 688, in _load_unlocked
  File "<frozen importlib._bootstrap_external>", line 883, in exec_module
  File "<frozen importlib._bootstrap>", line 241, in _call_with_frames_removed
  File "/home/dell/mystore/customers/models.py", line 5, in <module>
    class Customer(models.Model):
  File "/home/dell/mystore/customers/models.py", line 10, in Customer
    password = models.Pas
AttributeError: module 'django.db.models' has no attribute 'Pas'
/home/dell/mystore/customers/models.py changed, reloading.
Watching for file changes with StatReloader
Exception in thread django-main-thread:
Traceback (most recent call last):
  File "/usr/lib/python3.10/threading.py", line 1016, in _bootstrap_inner
    self.run()
  File "/usr/lib/python3.10/threading.py", line 953, in run
    self._target(*self._args, **self._kwargs)
  File "/home/dell/mystorevenv/lib/python3.10/site-packages/django/utils/autoreload.py", line 64, in wrapper
    fn(*args, **kwargs)
  File "/home/dell/mystorevenv/lib/python3.10/site-packages/django/core/management/commands/runserver.py", line 126, in inner_run
    autoreload.raise_last_exception()
  File "/home/dell/mystorevenv/lib/python3.10/site-packages/django/utils/autoreload.py", line 87, in raise_last_exception
    raise _exception[1]
  File "/home/dell/mystorevenv/lib/python3.10/site-packages/django/core/management/__init__.py", line 394, in execute
    autoreload.check_errors(django.setup)()
  File "/home/dell/mystorevenv/lib/python3.10/site-packages/django/utils/autoreload.py", line 64, in wrapper
    fn(*args, **kwargs)
  File "/home/dell/mystorevenv/lib/python3.10/site-packages/django/__init__.py", line 24, in setup
    apps.populate(settings.INSTALLED_APPS)
  File "/home/dell/mystorevenv/lib/python3.10/site-packages/django/apps/registry.py", line 116, in populate
    app_config.import_models()
  File "/home/dell/mystorevenv/lib/python3.10/site-packages/django/apps/config.py", line 269, in import_models
    self.models_module = import_module(models_module_name)
  File "/usr/lib/python3.10/importlib/__init__.py", line 126, in import_module
    return _bootstrap._gcd_import(name[level:], package, level)
  File "<frozen importlib._bootstrap>", line 1050, in _gcd_import
  File "<frozen importlib._bootstrap>", line 1027, in _find_and_load
  File "<frozen importlib._bootstrap>", line 1006, in _find_and_load_unlocked
  File "<frozen importlib._bootstrap>", line 688, in _load_unlocked
  File "<frozen importlib._bootstrap_external>", line 879, in exec_module
  File "<frozen importlib._bootstrap_external>", line 1017, in get_code
  File "<frozen importlib._bootstrap_external>", line 947, in source_to_code
  File "<frozen importlib._bootstrap>", line 241, in _call_with_frames_removed
  File "/home/dell/mystore/customers/models.py", line 10
    password = models.
                      ^
SyntaxError: invalid syntax
/home/dell/mystore/customers/models.py changed, reloading.
Watching for file changes with StatReloader
Exception in thread django-main-thread:
Traceback (most recent call last):
  File "/usr/lib/python3.10/threading.py", line 1016, in _bootstrap_inner
    self.run()
  File "/usr/lib/python3.10/threading.py", line 953, in run
    self._target(*self._args, **self._kwargs)
  File "/home/dell/mystorevenv/lib/python3.10/site-packages/django/utils/autoreload.py", line 64, in wrapper
    fn(*args, **kwargs)
  File "/home/dell/mystorevenv/lib/python3.10/site-packages/django/core/management/commands/runserver.py", line 126, in inner_run
    autoreload.raise_last_exception()
  File "/home/dell/mystorevenv/lib/python3.10/site-packages/django/utils/autoreload.py", line 87, in raise_last_exception
    raise _exception[1]
  File "/home/dell/mystorevenv/lib/python3.10/site-packages/django/core/management/__init__.py", line 394, in execute
    autoreload.check_errors(django.setup)()
  File "/home/dell/mystorevenv/lib/python3.10/site-packages/django/utils/autoreload.py", line 64, in wrapper
    fn(*args, **kwargs)
  File "/home/dell/mystorevenv/lib/python3.10/site-packages/django/__init__.py", line 24, in setup
    apps.populate(settings.INSTALLED_APPS)
  File "/home/dell/mystorevenv/lib/python3.10/site-packages/django/apps/registry.py", line 116, in populate
    app_config.import_models()
  File "/home/dell/mystorevenv/lib/python3.10/site-packages/django/apps/config.py", line 269, in import_models
    self.models_module = import_module(models_module_name)
  File "/usr/lib/python3.10/importlib/__init__.py", line 126, in import_module
    return _bootstrap._gcd_import(name[level:], package, level)
  File "<frozen importlib._bootstrap>", line 1050, in _gcd_import
  File "<frozen importlib._bootstrap>", line 1027, in _find_and_load
  File "<frozen importlib._bootstrap>", line 1006, in _find_and_load_unlocked
  File "<frozen importlib._bootstrap>", line 688, in _load_unlocked
  File "<frozen importlib._bootstrap_external>", line 883, in exec_module
  File "<frozen importlib._bootstrap>", line 241, in _call_with_frames_removed
  File "/home/dell/mystore/customers/models.py", line 5, in <module>
    class Customer(models.Model):
  File "/home/dell/mystore/customers/models.py", line 10, in Customer
    password = models.CH
AttributeError: module 'django.db.models' has no attribute 'CH'
/home/dell/mystore/customers/models.py changed, reloading.
Watching for file changes with StatReloader
Performing system checks...

System check identified some issues:

WARNINGS:
customers.Customer.phone: (fields.W122) 'max_length' is ignored when used with IntegerField.
        HINT: Remove 'max_length' from field

System check identified 1 issue (0 silenced).
October 31, 2024 - 21:16:14
Django version 5.1, using settings 'mystore.settings'
Starting development server at http://127.0.0.1:8000/
Quit the server with CONTROL-C.

/home/dell/mystore/customers/models.py changed, reloading.
Watching for file changes with StatReloader
Performing system checks...

System check identified some issues:

WARNINGS:
customers.Customer.phone: (fields.W122) 'max_length' is ignored when used with IntegerField.
        HINT: Remove 'max_length' from field

System check identified 1 issue (0 silenced).
October 31, 2024 - 21:16:27
Django version 5.1, using settings 'mystore.settings'
Starting development server at http://127.0.0.1:8000/
Quit the server with CONTROL-C.

/home/dell/mystore/customers/models.py changed, reloading.
Watching for file changes with StatReloader
Exception in thread django-main-thread:
Traceback (most recent call last):
  File "/usr/lib/python3.10/threading.py", line 1016, in _bootstrap_inner
    self.run()
  File "/usr/lib/python3.10/threading.py", line 953, in run
    self._target(*self._args, **self._kwargs)
  File "/home/dell/mystorevenv/lib/python3.10/site-packages/django/utils/autoreload.py", line 64, in wrapper
    fn(*args, **kwargs)
  File "/home/dell/mystorevenv/lib/python3.10/site-packages/django/core/management/commands/runserver.py", line 126, in inner_run
    autoreload.raise_last_exception()
  File "/home/dell/mystorevenv/lib/python3.10/site-packages/django/utils/autoreload.py", line 87, in raise_last_exception
    raise _exception[1]
  File "/home/dell/mystorevenv/lib/python3.10/site-packages/django/core/management/__init__.py", line 394, in execute
    autoreload.check_errors(django.setup)()
  File "/home/dell/mystorevenv/lib/python3.10/site-packages/django/utils/autoreload.py", line 64, in wrapper
    fn(*args, **kwargs)
  File "/home/dell/mystorevenv/lib/python3.10/site-packages/django/__init__.py", line 24, in setup
    apps.populate(settings.INSTALLED_APPS)
  File "/home/dell/mystorevenv/lib/python3.10/site-packages/django/apps/registry.py", line 116, in populate
    app_config.import_models()
  File "/home/dell/mystorevenv/lib/python3.10/site-packages/django/apps/config.py", line 269, in import_models
    self.models_module = import_module(models_module_name)
  File "/usr/lib/python3.10/importlib/__init__.py", line 126, in import_module
    return _bootstrap._gcd_import(name[level:], package, level)
  File "<frozen importlib._bootstrap>", line 1050, in _gcd_import
  File "<frozen importlib._bootstrap>", line 1027, in _find_and_load
  File "<frozen importlib._bootstrap>", line 1006, in _find_and_load_unlocked
  File "<frozen importlib._bootstrap>", line 688, in _load_unlocked
  File "<frozen importlib._bootstrap_external>", line 883, in exec_module
  File "<frozen importlib._bootstrap>", line 241, in _call_with_frames_removed
  File "/home/dell/mystore/customers/models.py", line 5, in <module>
    class Customer(models.Model):
  File "/home/dell/mystore/customers/models.py", line 10, in Customer
    password = models.CharField(ma)
NameError: name 'ma' is not defined. Did you mean: 'max'?
/home/dell/mystore/customers/models.py changed, reloading.
Watching for file changes with StatReloader
Performing system checks...

System check identified some issues:

WARNINGS:
customers.Customer.phone: (fields.W122) 'max_length' is ignored when used with IntegerField.
        HINT: Remove 'max_length' from field

System check identified 1 issue (0 silenced).
October 31, 2024 - 21:16:31
Django version 5.1, using settings 'mystore.settings'
Starting development server at http://127.0.0.1:8000/
Quit the server with CONTROL-C.

/home/dell/mystore/customers/models.py changed, reloading.
Watching for file changes with StatReloader
Exception in thread django-main-thread:
Traceback (most recent call last):
  File "/usr/lib/python3.10/threading.py", line 1016, in _bootstrap_inner
    self.run()
  File "/usr/lib/python3.10/threading.py", line 953, in run
    self._target(*self._args, **self._kwargs)
  File "/home/dell/mystorevenv/lib/python3.10/site-packages/django/utils/autoreload.py", line 64, in wrapper
    fn(*args, **kwargs)
  File "/home/dell/mystorevenv/lib/python3.10/site-packages/django/core/management/commands/runserver.py", line 126, in inner_run
    autoreload.raise_last_exception()
  File "/home/dell/mystorevenv/lib/python3.10/site-packages/django/utils/autoreload.py", line 87, in raise_last_exception
    raise _exception[1]
  File "/home/dell/mystorevenv/lib/python3.10/site-packages/django/core/management/__init__.py", line 394, in execute
    autoreload.check_errors(django.setup)()
  File "/home/dell/mystorevenv/lib/python3.10/site-packages/django/utils/autoreload.py", line 64, in wrapper
    fn(*args, **kwargs)
  File "/home/dell/mystorevenv/lib/python3.10/site-packages/django/__init__.py", line 24, in setup
    apps.populate(settings.INSTALLED_APPS)
  File "/home/dell/mystorevenv/lib/python3.10/site-packages/django/apps/registry.py", line 116, in populate
    app_config.import_models()
  File "/home/dell/mystorevenv/lib/python3.10/site-packages/django/apps/config.py", line 269, in import_models
    self.models_module = import_module(models_module_name)
  File "/usr/lib/python3.10/importlib/__init__.py", line 126, in import_module
    return _bootstrap._gcd_import(name[level:], package, level)
  File "<frozen importlib._bootstrap>", line 1050, in _gcd_import
  File "<frozen importlib._bootstrap>", line 1027, in _find_and_load
  File "<frozen importlib._bootstrap>", line 1006, in _find_and_load_unlocked
  File "<frozen importlib._bootstrap>", line 688, in _load_unlocked
  File "<frozen importlib._bootstrap_external>", line 883, in exec_module
  File "<frozen importlib._bootstrap>", line 241, in _call_with_frames_removed
  File "/home/dell/mystore/customers/models.py", line 5, in <module>
    class Customer(models.Model):
  File "/home/dell/mystore/customers/models.py", line 10, in Customer
    password = models.CharField(m)
NameError: name 'm' is not defined
/home/dell/mystore/customers/models.py changed, reloading.
Watching for file changes with StatReloader
Performing system checks...

System check identified some issues:

WARNINGS:
customers.Customer.phone: (fields.W122) 'max_length' is ignored when used with IntegerField.
        HINT: Remove 'max_length' from field

System check identified 1 issue (0 silenced).
October 31, 2024 - 21:16:44
Django version 5.1, using settings 'mystore.settings'
Starting development server at http://127.0.0.1:8000/
Quit the server with CONTROL-C.

/home/dell/mystore/customers/models.py changed, reloading.
Watching for file changes with StatReloader
Exception in thread django-main-thread:
Traceback (most recent call last):
  File "/usr/lib/python3.10/threading.py", line 1016, in _bootstrap_inner
    self.run()
  File "/usr/lib/python3.10/threading.py", line 953, in run
    self._target(*self._args, **self._kwargs)
  File "/home/dell/mystorevenv/lib/python3.10/site-packages/django/utils/autoreload.py", line 64, in wrapper
    fn(*args, **kwargs)
  File "/home/dell/mystorevenv/lib/python3.10/site-packages/django/core/management/commands/runserver.py", line 126, in inner_run
    autoreload.raise_last_exception()
  File "/home/dell/mystorevenv/lib/python3.10/site-packages/django/utils/autoreload.py", line 87, in raise_last_exception
    raise _exception[1]
  File "/home/dell/mystorevenv/lib/python3.10/site-packages/django/core/management/__init__.py", line 394, in execute
    autoreload.check_errors(django.setup)()
  File "/home/dell/mystorevenv/lib/python3.10/site-packages/django/utils/autoreload.py", line 64, in wrapper
    fn(*args, **kwargs)
  File "/home/dell/mystorevenv/lib/python3.10/site-packages/django/__init__.py", line 24, in setup
    apps.populate(settings.INSTALLED_APPS)
  File "/home/dell/mystorevenv/lib/python3.10/site-packages/django/apps/registry.py", line 116, in populate
    app_config.import_models()
  File "/home/dell/mystorevenv/lib/python3.10/site-packages/django/apps/config.py", line 269, in import_models
    self.models_module = import_module(models_module_name)
  File "/usr/lib/python3.10/importlib/__init__.py", line 126, in import_module
    return _bootstrap._gcd_import(name[level:], package, level)
  File "<frozen importlib._bootstrap>", line 1050, in _gcd_import
  File "<frozen importlib._bootstrap>", line 1027, in _find_and_load
  File "<frozen importlib._bootstrap>", line 1006, in _find_and_load_unlocked
  File "<frozen importlib._bootstrap>", line 688, in _load_unlocked
  File "<frozen importlib._bootstrap_external>", line 883, in exec_module
  File "<frozen importlib._bootstrap>", line 241, in _call_with_frames_removed
  File "/home/dell/mystore/customers/models.py", line 5, in <module>
    class Customer(models.Model):
  File "/home/dell/mystore/customers/models.py", line 10, in Customer
    password = models.CharField(m)
NameError: name 'm' is not defined
/home/dell/mystore/customers/models.py changed, reloading.
Watching for file changes with StatReloader
Performing system checks...

System check identified some issues:

WARNINGS:
customers.Customer.phone: (fields.W122) 'max_length' is ignored when used with IntegerField.
        HINT: Remove 'max_length' from field

System check identified 1 issue (0 silenced).
October 31, 2024 - 21:18:29
Django version 5.1, using settings 'mystore.settings'
Starting development server at http://127.0.0.1:8000/
Quit the server with CONTROL-C.

[31/Oct/2024 21:19:18] "GET /customers/account?csrfmiddlewaretoken=lVperkQQcXUMeKDyBspLobwGuz9hCAQsISm2icKmBKMAfgqBtZbKCiGT3YzdCrur&username=ren&password=ren1234&email=bhgbhb%40mkg&register= HTTP/1.1" 200 6690
[31/Oct/2024 21:20:20] "GET /admin/auth/user/?_facets=True HTTP/1.1" 200 12274
[31/Oct/2024 21:20:21] "GET /admin/jsi18n/ HTTP/1.1" 200 3342
[31/Oct/2024 21:20:24] "GET /admin/auth/user/?_facets=True HTTP/1.1" 200 12274
[31/Oct/2024 21:20:24] "GET /admin/jsi18n/ HTTP/1.1" 200 3342
[31/Oct/2024 21:20:30] "GET /admin/ HTTP/1.1" 200 10435
[31/Oct/2024 21:20:50] "GET / HTTP/1.1" 200 12236
[31/Oct/2024 21:20:50] "GET /media/media/product-9_cDMf07t.jpg HTTP/1.1" 304 0
[31/Oct/2024 21:21:00] "GET /admin/ HTTP/1.1" 200 10435
[31/Oct/2024 21:21:07] "GET / HTTP/1.1" 200 12236
[31/Oct/2024 21:21:16] "GET /customers/account HTTP/1.1" 200 6690
[31/Oct/2024 21:21:56] "GET /customers/account?csrfmiddlewaretoken=MbFCBJopcd80nmALGQexwTSVBBagf1Ri98CqsBiVB00OoSnOyn0wK028a0AcfSvh&username=ren&password=ren1234&email=ren%40dash.com&register= HTTP/1.1" 200 6690
